Workbook

Sheet Summary
A1: ANZSMM 2022 - TEMPLATE_V1.0
A3: Code | B3: Description | C3: Total | D3: % of Job | E3: POCD | F3: TOTAL EX | G3: GST | H3: TOTAL TENDER SUM
A4: 0 | B4: DISCLAIMER | C4: ='0-DISCLAIMER'!F1 -> 0 | D4: =IFERROR(C4/C$49,0) -> 0 | E4: =D4*C$55 -> 0 | F4: =C4+E4 -> 0 | G4: =D4*C$58 -> 0 | H4: =G4+F4 -> 0
A5: 1 | B5: GENERAL | C5: =SUM('1-GENERAL'!F1) -> 0 | D5: =IFERROR(C5/C$49,0) -> 0 | E5: =D5*C$55 -> 0 | F5: =C5+E5 -> 0 | G5: =D5*C$58 -> 0 | H5: =G5+F5 -> 0
A6: 2 | B6: PRELIMINARIES | C6: =SUM('2-PRELIMINARIES'!F1) -> 0 | D6: =IFERROR(C6/C$49,0) -> 0 | E6: =D6*C$55 -> 0 | F6: =C6+E6 -> 0 | G6: =D6*C$58 -> 0 | H6: =G6+F6 -> 0
A7: 3 | B7: DEMOLITION | C7: =SUM('3-DEMOLITION'!F1) -> 0 | D7: =IFERROR(C7/C$49,0) -> 0 | E7: =D7*C$55 -> 0 | F7: =C7+E7 -> 0 | G7: =D7*C$58 -> 0 | H7: =G7+F7 -> 0
A8: 4 | B8: GROUNDWORKS | C8: =SUM('4-GROUNDWORKS'!F1) -> 0 | D8: =IFERROR(C8/C$49,0) -> 0 | E8: =D8*C$55 -> 0 | F8: =C8+E8 -> 0 | G8: =D8*C$58 -> 0 | H8: =G8+F8 -> 0
A9: 5 | B9: PILING | C9: =SUM('5-PILING'!F1) -> 0 | D9: =IFERROR(C9/C$49,0) -> 0 | E9: =D9*C$55 -> 0 | F9: =C9+E9 -> 0 | G9: =D9*C$58 -> 0 | H9: =G9+F9 -> 0
A10: 6 | B10: CONCRETE | C10: =SUM('6-CONCRETE'!F1) -> 0 | D10: =IFERROR(C10/C$49,0) -> 0 | E10: =D10*C$55 -> 0 | F10: =C10+E10 -> 0 | G10: =D10*C$58 -> 0 | H10: =G10+F10 -> 0
A11: 7 | B11: FORMWORK | C11: =SUM('7-FORMWORK'!F1) -> 0 | D11: =IFERROR(C11/C$49,0) -> 0 | E11: =D11*C$55 -> 0 | F11: =C11+E11 -> 0 | G11: =D11*C$58 -> 0 | H11: =G11+F11 -> 0
A12: 8 | B12: REINFORCEMENT | C12: =SUM('8-REINFORCEMENT'!F1) -> 0 | D12: =IFERROR(C12/C$49,0) -> 0 | E12: =D12*C$55 -> 0 | F12: =C12+E12 -> 0 | G12: =D12*C$58 -> 0 | H12: =G12+F12 -> 0
A13: 9 | B13: PRESTRESSING | C13: =SUM('9-PRESTRESSING'!F1) -> 0 | D13: =IFERROR(C13/C$49,0) -> 0 | E13: =D13*C$55 -> 0 | F13: =C13+E13 -> 0 | G13: =D13*C$58 -> 0 | H13: =G13+F13 -> 0
A14: 10 | B14: PRECAST CONCRETE | C14: =SUM('10-PRECAST CONCRETE'!F1) -> 0 | D14: =IFERROR(C14/C$49,0) -> 0 | E14: =D14*C$55 -> 0 | F14: =C14+E14 -> 0 | G14: =D14*C$58 -> 0 | H14: =G14+F14 -> 0
A15: 11 | B15: TANKING AND WATERPROOF MEMBRANES | C15: =SUM('11-TANKING AND WATERPROOF MEMBR'!F1) -> 0 | D15: =IFERROR(C15/C$49,0) -> 0 | E15: =D15*C$55 -> 0 | F15: =C15+E15 -> 0 | G15: =D15*C$58 -> 0 | H15: =G15+F15 -> 0
A16: 12 | B16: MASONRY | C16: =SUM('12-MASONRY'!F1) -> 0 | D16: =IFERROR(C16/C$49,0) -> 0 | E16: =D16*C$55 -> 0 | F16: =C16+E16 -> 0 | G16: =D16*C$58 -> 0 | H16: =G16+F16 -> 0
A17: 13 | B17: STONEWORK | C17: =SUM('13-STONEWORK'!F1) -> 0 | D17: =IFERROR(C17/C$49,0) -> 0 | E17: =D17*C$55 -> 0 | F17: =C17+E17 -> 0 | G17: =D17*C$58 -> 0 | H17: =G17+F17 -> 0
A18: 14 | B18: STRUCTURAL STEEL | C18: =SUM('14-STRUCTURAL STEEL'!F1) -> 0 | D18: =IFERROR(C18/C$49,0) -> 0 | E18: =D18*C$55 -> 0 | F18: =C18+E18 -> 0 | G18: =D18*C$58 -> 0 | H18: =G18+F18 -> 0
A19: 15 | B19: METALWORK | C19: =SUM('15-METALWORK'!F1) -> 0 | D19: =IFERROR(C19/C$49,0) -> 0 | E19: =D19*C$55 -> 0 | F19: =C19+E19 -> 0 | G19: =D19*C$58 -> 0 | H19: =G19+F19 -> 0
A20: 16 | B20: ROOFING | C20: =SUM('16-ROOFING'!F1) -> 0 | D20: =IFERROR(C20/C$49,0) -> 0 | E20: =D20*C$55 -> 0 | F20: =C20+E20 -> 0 | G20: =D20*C$58 -> 0 | H20: =G20+F20 -> 0
A21: 17 | B21: FAÇADE SYSTEMS | C21: =SUM('17-FAÇADE SYSTEMS'!F1) -> 0 | D21: =IFERROR(C21/C$49,0) -> 0 | E21: =D21*C$55 -> 0 | F21: =C21+E21 -> 0 | G21: =D21*C$58 -> 0 | H21: =G21+F21 -> 0
A22: 18 | B22: WINDOWS | C22: =SUM('18-WINDOWS'!F1) -> 0 | D22: =IFERROR(C22/C$49,0) -> 0 | E22: =D22*C$55 -> 0 | F22: =C22+E22 -> 0 | G22: =D22*C$58 -> 0 | H22: =G22+F22 -> 0
A23: 19 | B23: GLAZING | C23: =SUM('19-GLAZING'!F1) -> 0 | D23: =IFERROR(C23/C$49,0) -> 0 | E23: =D23*C$55 -> 0 | F23: =C23+E23 -> 0 | G23: =D23*C$58 -> 0 | H23: =G23+F23 -> 0
A24: 20 | B24: CARPENTRY | C24: =SUM('20-CARPENTRY'!F1) -> 0 | D24: =IFERROR(C24/C$49,0) -> 0 | E24: =D24*C$55 -> 0 | F24: =C24+E24 -> 0 | G24: =D24*C$58 -> 0 | H24: =G24+F24 -> 0
A25: 21 | B25: PARTITIONS | C25: =SUM('21-PARTITIONS'!F1) -> 0 | D25: =IFERROR(C25/C$49,0) -> 0 | E25: =D25*C$55 -> 0 | F25: =C25+E25 -> 0 | G25: =D25*C$58 -> 0 | H25: =G25+F25 -> 0
A26: 22 | B26: SUSPENDED CEILINGS | C26: =SUM('22-SUSPENDED CEILINGS'!F1) -> 0 | D26: =IFERROR(C26/C$49,0) -> 0 | E26: =D26*C$55 -> 0 | F26: =C26+E26 -> 0 | G26: =D26*C$58 -> 0 | H26: =G26+F26 -> 0
A27: 23 | B27: ACCESS FLOORS | C27: =SUM('23-ACCESS FLOORS'!F1) -> 0 | D27: =IFERROR(C27/C$49,0) -> 0 | E27: =D27*C$55 -> 0 | F27: =C27+E27 -> 0 | G27: =D27*C$58 -> 0 | H27: =G27+F27 -> 0
A28: 24 | B28: DOORS | C28: =SUM('24-DOORS'!F1) -> 0 | D28: =IFERROR(C28/C$49,0) -> 0 | E28: =D28*C$55 -> 0 | F28: =C28+E28 -> 0 | G28: =D28*C$58 -> 0 | H28: =G28+F28 -> 0
A29: 25 | B29: HARDWARE | C29: =SUM('25-HARDWARE'!F1) -> 0 | D29: =IFERROR(C29/C$49,0) -> 0 | E29: =D29*C$55 -> 0 | F29: =C29+E29 -> 0 | G29: =D29*C$58 -> 0 | H29: =G29+F29 -> 0
A30: 26 | B30: APPLIED FINISHES, RENDER & TEXTURED FINISHES | C30: =SUM('26-APPLIED FINISHES, RENDER & T'!F1) -> 0 | D30: =IFERROR(C30/C$49,0) -> 0 | E30: =D30*C$55 -> 0 | F30: =C30+E30 -> 0 | G30: =D30*C$58 -> 0 | H30: =G30+F30 -> 0
A31: 27 | B31: TILING, SLAB AND PAVING | C31: =SUM('27-TILING, SLAB AND PAVING'!F1) -> 0 | D31: =IFERROR(C31/C$49,0) -> 0 | E31: =D31*C$55 -> 0 | F31: =C31+E31 -> 0 | G31: =D31*C$58 -> 0 | H31: =G31+F31 -> 0
A32: 28 | B32: CARPET AND RESILIENT FINISHES | C32: =SUM('28-CARPET AND RESILIENT FINISHE'!F1) -> 0 | D32: =IFERROR(C32/C$49,0) -> 0 | E32: =D32*C$55 -> 0 | F32: =C32+E32 -> 0 | G32: =D32*C$58 -> 0 | H32: =G32+F32 -> 0
A33: 29 | B33: PAINTING | C33: =SUM('29-PAINTING'!F1) -> 0 | D33: =IFERROR(C33/C$49,0) -> 0 | E33: =D33*C$55 -> 0 | F33: =C33+E33 -> 0 | G33: =D33*C$58 -> 0 | H33: =G33+F33 -> 0
A34: 30 | B34: JOINERY | C34: ='30-JOINERY'!F1 -> 0 | D34: =IFERROR(C34/C$49,0) -> 0 | E34: =D34*C$55 -> 0 | F34: =C34+E34 -> 0 | G34: =D34*C$58 -> 0 | H34: =G34+F34 -> 0
A35: 31 | B35: FURNITURE FITTINGS AND EQUIPMENT | C35: =SUM('31-FURNITURE FITTINGS AND EQUIP'!F1) -> 0 | D35: =IFERROR(C35/C$49,0) -> 0 | E35: =D35*C$55 -> 0 | F35: =C35+E35 -> 0 | G35: =D35*C$58 -> 0 | H35: =G35+F35 -> 0
A36: 32 | B36: HYDRAULICS | C36: =SUM('32-HYDRAULICS'!F1) -> 0 | D36: =IFERROR(C36/C$49,0) -> 0 | E36: =D36*C$55 -> 0 | F36: =C36+E36 -> 0 | G36: =D36*C$58 -> 0 | H36: =G36+F36 -> 0
A37: 33 | B37: DRAINAGE | C37: =SUM('33-DRAINAGE'!F1) -> 0 | D37: =IFERROR(C37/C$49,0) -> 0 | E37: =D37*C$55 -> 0 | F37: =C37+E37 -> 0 | G37: =D37*C$58 -> 0 | H37: =G37+F37 -> 0
A38: 34 | B38: ELECTRICAL INSTALLATIONS | C38: =SUM('34-ELECTRICAL INSTALLATIONS'!F1) -> 0 | D38: =IFERROR(C38/C$49,0) -> 0 | E38: =D38*C$55 -> 0 | F38: =C38+E38 -> 0 | G38: =D38*C$58 -> 0 | H38: =G38+F38 -> 0
A39: 35 | B39: MECHANICAL INSTALLATIONS | C39: =SUM('35-MECHANICAL INSTALLATIONS'!F1) -> 0 | D39: =IFERROR(C39/C$49,0) -> 0 | E39: =D39*C$55 -> 0 | F39: =C39+E39 -> 0 | G39: =D39*C$58 -> 0 | H39: =G39+F39 -> 0
A40: 36 | B40: TRANSPORTATION SERVICES | C40: =SUM('36-TRANSPORTATION SERVICES'!F1) -> 0 | D40: =IFERROR(C40/C$49,0) -> 0 | E40: =D40*C$55 -> 0 | F40: =C40+E40 -> 0 | G40: =D40*C$58 -> 0 | H40: =G40+F40 -> 0
A41: 37 | B41: EXTERIOR ELEMENTS | C41: =SUM('37-EXTERIOR ELEMENTS'!F1) -> 0 | D41: =IFERROR(C41/C$49,0) -> 0 | E41: =D41*C$55 -> 0 | F41: =C41+E41 -> 0 | G41: =D41*C$58 -> 0 | H41: =G41+F41 -> 0
...

Sheet 0-DISCLAIMER
A1: DISCLAIMER | E1: HOME | F1: =SUM(F2:F1000)/2 -> 0
A2: Code | B2: Description | C2: Quantity | D2: Unit | E2: Rate | F2: Total
B3: General Items | C3: 0
B4: CD Consult's (CDC) service is provided to assist Customers to estimate required product quantities & project prices. While CDC endeavours to provide you with the product quantities based on your stated job requirements, it is the responsibility of the end user (builder, architect, home owner etc) to check and confirm whether all quantities are correct and reasonable.
B5: Please note that CDC is not providing advice on which products are suitable for the job's requirements. It is the responsibility of the end user to specify the kind of products you want to use for each application.
B6: Any opinions herein are to be verified by others. We do not assume responsibility for incomplete documentation. Any items not specifically detailed where a product may be included by CDC are to be considered to have the words "...or equivalent to be verified by others" inserted after them.
B7: If you encounter any bugs or issues, please contact us immediately.
B8: Intended Client
B9: This estimate has been prepared for exclusive use by:
B10: BUILDER
B11: The contents of this cost report are non transferable to any other person or entity. This estimate remains the property of the issuer and for mentioned user.

Sheet 1-GENERAL
A1: GENERAL | E1: HOME | F1: =SUM(F2:F1000)/2 -> 0
A2: Code | B2: Description | C2: Quantity | D2: Unit | E2: Rate | F2: Total
B3: GENERAL | C3: 1 | D3: HEAD
B4: In accordance with The Australian Standard Method of Measurement Section 1 part 3.1 'Unless otherwise stated in this bill of quantities, work shall be measured net as fixed in position i.e.No waste has been allowed for. | C4: 1 | D4: note
B5: This cost plan has been measured as per ASMM 6. standard dinension groups where a list and process was provided for quantities required. | C5: 1 | D5: note
B6: All levels referred to in this cost plan are relevant to the architectural drawings. | C6: 1 | D6: note
B7: All prices quoted are to be used as a guide only. | C7: 1 | D7: note
B8: All proprietary names included in this Bill of Quantities will be deemed to have the words 'or equal approved' inserted after them. | C8: 1 | D8: note
B9: All dimensions stated are approximate only and the Contractor will be deemed to have verified by inspection the full nature, scope and extent of the relevant work . | C9: 1 | D9: note
B11: DOCUMENTATION | C11: 1 | D11: HEAD
B12: This cost plan has been measured off the following documents: | C12: 1 | D12: note
B14: Architectural drawings prepared by: | C14: 1 | D14: note
B15: <>
B16: Job Number:
B17: <>
B18: Sheets:
B19: <>
B20: Being:
B21: <>
B22: Revision:
B23: <>
B25: Land survey prepared by: | C25: 1 | D25: note
B26: <>
B27: Job Number:
B28: <>
B29: Sheets:
B30: <>
B31: Being:
B32: <>
B33: Revision:
B34: <>
B36: BASIX/NATHERS Report Prepared By: | C36: 1 | D36: note
B37: <>
B38: Job Number:
B39: <>
B40: Sheets:
B41: <>
B42: Being:
B43: <>
B44: Revision:
...

Sheet 2-PRELIMINARIES
A1: PRELIMINARIES | E1: HOME | F1: =SUM(F2:F1000)/2 -> 0
A2: Code | B2: Description | C2: Quantity | D2: Unit | E2: Rate | F2: Total
A3: a | B3: Example | C3: 1 | D3: ea
B4: Total | F4: =SUM(F2:F3) -> 0

Sheet 3-DEMOLITION
A1: DEMOLITION | E1: HOME | F1: =SUM(F2:F1000)/2 -> 0
A2: Code | B2: Description | C2: Quantity | D2: Unit | E2: Rate | F2: Total
A3: a | B3: Example | C3: 1 | D3: ea
B4: Total | F4: =SUM(F2:F3) -> 0

Sheet 4-GROUNDWORKS
A1: GROUNDWORKS | E1: HOME | F1: =SUM(F2:F1000)/2 -> 0
A2: Code | B2: Description | C2: Quantity | D2: Unit | E2: Rate | F2: Total
A3: a | B3: Example | C3: 1 | D3: ea
B4: Total | F4: =SUM(F2:F3) -> 0

Sheet 5-PILING
A1: PILING | E1: HOME | F1: =SUM(F2:F1000)/2 -> 0
A2: Code | B2: Description | C2: Quantity | D2: Unit | E2: Rate | F2: Total
A3: a | B3: Example | C3: 1 | D3: ea
B4: Total | F4: =SUM(F2:F3) -> 0

Sheet 6-CONCRETE
A1: CONCRETE | E1: HOME | F1: =SUM(F2:F1000)/2 -> 0
A2: Code | B2: Description | C2: Quantity | D2: Unit | E2: Rate | F2: Total
A3: a | B3: Example | C3: 1 | D3: ea
B4: Total | F4: =SUM(F2:F3) -> 0

Sheet 7-FORMWORK
A1: FORMWORK | E1: HOME | F1: =SUM(F2:F1000)/2 -> 0
A2: Code | B2: Description | C2: Quantity | D2: Unit | E2: Rate | F2: Total
A3: a | B3: Example | C3: 1 | D3: ea
B4: Total | F4: =SUM(F2:F3) -> 0

Sheet 8-REINFORCEMENT
A1: REINFORCEMENT | E1: HOME | F1: =SUM(F2:F1000)/2 -> 0
A2: Code | B2: Description | C2: Quantity | D2: Unit | E2: Rate | F2: Total
A3: a | B3: Example | C3: 1 | D3: ea
B4: Total | F4: =SUM(F2:F3) -> 0

Sheet 9-PRESTRESSING
A1: PRESTRESSING | E1: HOME | F1: =SUM(F2:F1000)/2 -> 0
A2: Code | B2: Description | C2: Quantity | D2: Unit | E2: Rate | F2: Total
A3: a | B3: Example | C3: 1 | D3: ea
B4: Total | F4: =SUM(F2:F3) -> 0

Sheet 10-PRECAST CONCRETE
A1: PRECAST CONCRETE | E1: HOME | F1: =SUM(F2:F1000)/2 -> 0
A2: Code | B2: Description | C2: Quantity | D2: Unit | E2: Rate | F2: Total
A3: a | B3: Example | C3: 1 | D3: ea
B4: Total | F4: =SUM(F2:F3) -> 0

Sheet 11-TANKING AND WATERPROOF MEMBR
A1: TANKING AND WATERPROOF MEMBRANES | E1: HOME | F1: =SUM(F2:F1000)/2 -> 0
A2: Code | B2: Description | C2: Quantity | D2: Unit | E2: Rate | F2: Total
A3: a | B3: Example | C3: 1 | D3: ea
B4: Total | F4: =SUM(F2:F3) -> 0

Sheet 12-MASONRY
A1: MASONRY | E1: HOME | F1: =SUM(F2:F1000)/2 -> 0
A2: Code | B2: Description | C2: Quantity | D2: Unit | E2: Rate | F2: Total
A3: a | B3: Example | C3: 1 | D3: ea
B4: Total | F4: =SUM(F2:F3) -> 0

Sheet 13-STONEWORK
A1: STONEWORK | E1: HOME | F1: =SUM(F2:F1000)/2 -> 0
A2: Code | B2: Description | C2: Quantity | D2: Unit | E2: Rate | F2: Total
A3: a | B3: Example | C3: 1 | D3: ea
B4: Total | F4: =SUM(F2:F3) -> 0

Sheet 14-STRUCTURAL STEEL
A1: STRUCTURAL STEEL | E1: HOME | F1: =SUM(F2:F1000)/2 -> 0
A2: Code | B2: Description | C2: Quantity | D2: Unit | E2: Rate | F2: Total
A3: a | B3: Example | C3: 1 | D3: ea
B4: Total | F4: =SUM(F2:F3) -> 0

Sheet 15-METALWORK
A1: METALWORK | E1: HOME | F1: =SUM(F2:F1000)/2 -> 0
A2: Code | B2: Description | C2: Quantity | D2: Unit | E2: Rate | F2: Total
A3: a | B3: Example | C3: 1 | D3: ea
B4: Total | F4: =SUM(F2:F3) -> 0

Sheet 16-ROOFING
A1: ROOFING | E1: HOME | F1: =SUM(F2:F1000)/2 -> 0
A2: Code | B2: Description | C2: Quantity | D2: Unit | E2: Rate | F2: Total
A3: a | B3: Example | C3: 1 | D3: ea
B4: Total | F4: =SUM(F2:F3) -> 0

Sheet 17-FAÇADE SYSTEMS
A1: FAÇADE SYSTEMS | E1: HOME | F1: =SUM(F2:F1000)/2 -> 0
A2: Code | B2: Description | C2: Quantity | D2: Unit | E2: Rate | F2: Total
A3: a | B3: Example | C3: 1 | D3: ea
B4: Total | F4: =SUM(F2:F3) -> 0

Sheet 18-WINDOWS
A1: WINDOWS | E1: HOME | F1: =SUM(F2:F1000)/2 -> 0
A2: Code | B2: Description | C2: Quantity | D2: Unit | E2: Rate | F2: Total
A3: a | B3: Example | C3: 1 | D3: ea
B4: Total | F4: =SUM(F2:F3) -> 0

Sheet 19-GLAZING
A1: GLAZING | E1: HOME | F1: =SUM(F2:F1000)/2 -> 0
A2: Code | B2: Description | C2: Quantity | D2: Unit | E2: Rate | F2: Total
A3: a | B3: Example | C3: 1 | D3: ea
B4: Total | F4: =SUM(F2:F3) -> 0

Sheet 20-CARPENTRY
A1: CARPENTRY | E1: HOME | F1: =SUM(F2:F1000)/2 -> 0
A2: Code | B2: Description | C2: Quantity | D2: Unit | E2: Rate | F2: Total
A3: a | B3: Example | C3: 1 | D3: ea
B4: Total | F4: =SUM(F2:F3) -> 0

Sheet 21-PARTITIONS
A1: PARTITIONS | E1: HOME | F1: =SUM(F2:F1000)/2 -> 0
A2: Code | B2: Description | C2: Quantity | D2: Unit | E2: Rate | F2: Total
A3: a | B3: Example | C3: 1 | D3: ea
B4: Total | F4: =SUM(F2:F3) -> 0

Sheet 22-SUSPENDED CEILINGS
A1: SUSPENDED CEILINGS | E1: HOME | F1: =SUM(F2:F1000)/2 -> 0
A2: Code | B2: Description | C2: Quantity | D2: Unit | E2: Rate | F2: Total
A3: a | B3: Example | C3: 1 | D3: ea
B4: Total | F4: =SUM(F2:F3) -> 0

Sheet 23-ACCESS FLOORS
A1: ACCESS FLOORS | E1: HOME | F1: =SUM(F2:F1000)/2 -> 0
A2: Code | B2: Description | C2: Quantity | D2: Unit | E2: Rate | F2: Total
A3: a | B3: Example | C3: 1 | D3: ea
B4: Total | F4: =SUM(F2:F3) -> 0

Sheet 24-DOORS
A1: DOORS | E1: HOME | F1: =SUM(F2:F1000)/2 -> 0
A2: Code | B2: Description | C2: Quantity | D2: Unit | E2: Rate | F2: Total
A3: a | B3: Example | C3: 1 | D3: ea
B4: Total | F4: =SUM(F2:F3) -> 0

Sheet 25-HARDWARE
A1: HARDWARE | E1: HOME | F1: =SUM(F2:F1000)/2 -> 0
A2: Code | B2: Description | C2: Quantity | D2: Unit | E2: Rate | F2: Total
A3: a | B3: Example | C3: 1 | D3: ea
B4: Total | F4: =SUM(F2:F3) -> 0

Sheet 26-APPLIED FINISHES, RENDER & T
A1: APPLIED FINISHES, RENDER & TEXTURED FINISHES | E1: HOME | F1: =SUM(F2:F1000)/2 -> 0
A2: Code | B2: Description | C2: Quantity | D2: Unit | E2: Rate | F2: Total
A3: a | B3: Example | C3: 1 | D3: ea
B4: Total | F4: =SUM(F2:F3) -> 0

Sheet 27-TILING, SLAB AND PAVING
A1: TILING, SLAB AND PAVING | E1: HOME | F1: =SUM(F2:F1000)/2 -> 0
A2: Code | B2: Description | C2: Quantity | D2: Unit | E2: Rate | F2: Total
A3: a | B3: Example | C3: 1 | D3: ea
B4: Total | F4: =SUM(F2:F3) -> 0

Sheet 28-CARPET AND RESILIENT FINISHE
A1: CARPET AND RESILIENT FINISHES | E1: HOME | F1: =SUM(F2:F1000)/2 -> 0
A2: Code | B2: Description | C2: Quantity | D2: Unit | E2: Rate | F2: Total
A3: a | B3: Example | C3: 1 | D3: ea
B4: Total | F4: =SUM(F2:F3) -> 0

Sheet 29-PAINTING
A1: PAINTING | E1: HOME | F1: =SUM(F2:F1000)/2 -> 0
A2: Code | B2: Description | C2: Quantity | D2: Unit | E2: Rate | F2: Total
A3: a | B3: Example | C3: 1 | D3: ea
B4: Total | F4: =SUM(F2:F3) -> 0

Sheet 30-JOINERY
A1: JOINERY | E1: HOME | F1: =SUM(F2:F1000)/2 -> 0
A2: Code | B2: Description | C2: Quantity | D2: Unit | E2: Rate | F2: Total
A3: a | B3: Example | C3: 1 | D3: ea
B4: Total | F4: =SUM(F2:F3) -> 0

Sheet 31-FURNITURE FITTINGS AND EQUIP
A1: FURNITURE FITTINGS AND EQUIPMENT | E1: HOME | F1: =SUM(F2:F1000)/2 -> 0
A2: Code | B2: Description | C2: Quantity | D2: Unit | E2: Rate | F2: Total
A3: a | B3: Example | C3: 1 | D3: ea
B4: Total | F4: =SUM(F2:F3) -> 0

Sheet 32-HYDRAULICS
A1: HYDRAULICS | E1: HOME | F1: =SUM(F2:F1000)/2 -> 0
A2: Code | B2: Description | C2: Quantity | D2: Unit | E2: Rate | F2: Total
A3: a | B3: Example | C3: 1 | D3: ea
B4: Total | F4: =SUM(F2:F3) -> 0

Sheet 33-DRAINAGE
A1: DRAINAGE | E1: HOME | F1: =SUM(F2:F1000)/2 -> 0
A2: Code | B2: Description | C2: Quantity | D2: Unit | E2: Rate | F2: Total
A3: a | B3: Example | C3: 1 | D3: ea
B4: Total | F4: =SUM(F2:F3) -> 0

Sheet 34-ELECTRICAL INSTALLATIONS
A1: ELECTRICAL INSTALLATIONS | E1: HOME | F1: =SUM(F2:F1000)/2 -> 0
A2: Code | B2: Description | C2: Quantity | D2: Unit | E2: Rate | F2: Total
A3: a | B3: Example | C3: 1 | D3: ea
B4: Total | F4: =SUM(F2:F3) -> 0

Sheet 35-MECHANICAL INSTALLATIONS
A1: MECHANICAL INSTALLATIONS | E1: HOME | F1: =SUM(F2:F1000)/2 -> 0
A2: Code | B2: Description | C2: Quantity | D2: Unit | E2: Rate | F2: Total
A3: a | B3: Example | C3: 1 | D3: ea
B4: Total | F4: =SUM(F2:F3) -> 0

Sheet 36-TRANSPORTATION SERVICES
A1: TRANSPORTATION SERVICES | E1: HOME | F1: =SUM(F2:F1000)/2 -> 0
A2: Code | B2: Description | C2: Quantity | D2: Unit | E2: Rate | F2: Total
A3: a | B3: Example | C3: 1 | D3: ea
B4: Total | F4: =SUM(F2:F3) -> 0

Sheet 37-EXTERIOR ELEMENTS
A1: EXTERIOR ELEMENTS | E1: HOME | F1: =SUM(F2:F1000)/2 -> 0
A2: Code | B2: Description | C2: Quantity | D2: Unit | E2: Rate | F2: Total
A3: a | B3: Example | C3: 1 | D3: ea
B4: Total | F4: =SUM(F2:F3) -> 0

Sheet 38-FIRE PROTECTION
A1: FIRE PROTECTION | E1: HOME | F1: =SUM(F2:F1000)/2 -> 0
A2: Code | B2: Description | C2: Quantity | D2: Unit | E2: Rate | F2: Total
A3: a | B3: Example | C3: 1 | D3: ea
B4: Total | F4: =SUM(F2:F3) -> 0

Sheet 39-INCLUDED SUMS
A1: INCLUDED SUMS | E1: HOME | F1: =SUM(F2:F1000)/2 -> 0
A2: Code | B2: Description | C2: Quantity | D2: Unit | E2: Rate | F2: Total
A3: a | B3: Example | C3: 1 | D3: ea
B4: Total | F4: =SUM(F2:F3) -> 0

Sheet 40-SIGNAGE
A1: SIGNAGE | E1: HOME | F1: =SUM(F2:F1000)/2 -> 0
A2: Code | B2: Description | C2: Quantity | D2: Unit | E2: Rate | F2: Total
A3: a | B3: Example | C3: 1 | D3: ea
B4: Total | F4: =SUM(F2:F3) -> 0

Sheet 41-PEST CONTROL
A1: PEST CONTROL | E1: HOME | F1: =SUM(F2:F1000)/2 -> 0
A2: Code | B2: Description | C2: Quantity | D2: Unit | E2: Rate | F2: Total
A3: a | B3: Example | C3: 1 | D3: ea
B4: Total | F4: =SUM(F2:F3) -> 0

Sheet 42-WORKS BY NOMINATED SUBCONTRA
A1: WORKS BY NOMINATED SUBCONTRACTORS | E1: HOME | F1: =SUM(F2:F1000)/2 -> 0
A2: Code | B2: Description | C2: Quantity | D2: Unit | E2: Rate | F2: Total
A3: a | B3: Example | C3: 1 | D3: ea
B4: Total | F4: =SUM(F2:F3) -> 0

Sheet 43-NOT INCLUDED ELSEWHERE
A1: NOT INCLUDED ELSEWHERE | E1: HOME | F1: =SUM(F2:F1000)/2 -> 0
A2: Code | B2: Description | C2: Quantity | D2: Unit | E2: Rate | F2: Total
A3: a | B3: Example | C3: 1 | D3: ea
B4: Total | F4: =SUM(F2:F3) -> 0

Sheet Sheet1
